Workbook

Sheet Sheet1
A1: Id | B1: Start time | C1: Completion time | D1: Email | E1: Name | F1: Total points | G1: Quiz feedback | H1: Grade posted time | I1: Seleccione el día de la defensa | J1: Points - Seleccione el día de la defensa | K1: Feedback - Seleccione el día de la defensa | L1: Seleccione su nombre (Evaluador) | M1: Control de duplicados | N1: Feedback - Seleccione su nombre (Evaluador) | O1: Seleccione el nombre del Estudiante | P1: Points - Seleccione el nombre del Estudiante | Q1: Feedback - Seleccione el nombre del Estudiante | R1: Apertura: problema y objetivo | S1: Points - Apertura: problema y objetivo | T1: Feedback - Apertura: problema y objetivo | U1: Metodología (nivel adecuado) | V1: Points - Metodología (nivel adecuado) | W1: Feedback - Metodología (nivel adecuado) | X1: Resultados y evidencia | Y1: Points - Resultados y evidencia | Z1: Feedback - Resultados y evidencia | AA1: Coherencia y manejo del tiempo | AB1: Points - Coherencia y manejo del tiempo | AC1: Feedback - Coherencia y manejo del tiempo | AD1: Diapositivas como apoyo | AE1: Points - Diapositivas como apoyo | AF1: Feedback - Diapositivas como apoyo | AG1: Respuestas a preguntas | AH1: Points - Respuestas a preguntas | AI1: Feedback - Respuestas a preguntas | AJ1: Cierre: aporte a próximos pasos | AK1: Points - Cierre: aporte a próximos pasos | AL1: Feedback - Cierre: aporte a próximos pasos | AM1: PUNTAJE APERTURA
A2: 1 | B2: 46133.32 | C2: 46133.371 | D2: patricio.ponce.herrera@udla.edu.ec | E2: Patricio David Ponce Herrera | I2: Martes 21 | J2: 0 | L2: Patricio David Ponce | M2: =CONCATENATE(TablaCalificaciones[[#This Row],[Seleccione su nombre (Evaluador)]],TablaCalificaciones[[#This Row],[Seleccione el nombre del Estudiante]]) -> Patricio David PonceSolano De La Sala Aldas Paúl Fernando | O2: Solano De La Sala Aldas Paúl Fernando | P2: 0 | R2: Excelente (20 puntos) | S2: =VLOOKUP(TablaCalificaciones[[#This Row],[Apertura: problema y objetivo ]],PESOS!A$16:B$20,2,0) -> 20 | U2: Excelente (20 puntos) | V2: =VLOOKUP(TablaCalificaciones[[#This Row],[Metodología (nivel adecuado)]],PESOS!A$16:B$20,2,0) -> 20 | X2: Excelente (20 puntos) | Y2: =VLOOKUP(TablaCalificaciones[[#This Row],[Resultados y evidencia ]],PESOS!A$16:B$20,2,0) -> 20 | AA2: Excelente (10 puntos) | AB2: =VLOOKUP(TablaCalificaciones[[#This Row],[Coherencia y manejo del tiempo]],PESOS!A$25:B$29,2,0) -> 10 | AD2: Excelente (10 puntos) | AE2: =VLOOKUP(TablaCalificaciones[[#This Row],[Diapositivas como apoyo]],PESOS!A$25:B$29,2,0) -> 10 | AG2: Excelente (10 puntos) | AH2: =VLOOKUP(TablaCalificaciones[[#This Row],[Respuestas a preguntas]],PESOS!A$25:B$29,2,0) -> 10 | AJ2: Excelente (10 puntos) | AK2: =VLOOKUP(TablaCalificaciones[[#This Row],[Cierre: aporte a próximos pasos]],PESOS!A$25:B$29,2,0) -> 10
A3: 2 | B3: 46133.374 | C3: 46133.377 | D3: bernarda.sandoval@udla.edu.ec | E3: Bernarda Cecibel Sandoval | I3: Martes 21 | J3: 0 | L3: Bernarda Sandoval Romo | M3: =CONCATENATE(TablaCalificaciones[[#This Row],[Seleccione su nombre (Evaluador)]],TablaCalificaciones[[#This Row],[Seleccione el nombre del Estudiante]]) -> Bernarda Sandoval RomoRojas González María Fernanda | O3: Rojas González María Fernanda | P3: 0 | R3: Excelente (20 puntos) | S3: =VLOOKUP(TablaCalificaciones[[#This Row],[Apertura: problema y objetivo ]],PESOS!A$16:B$20,2,0) -> 20 | U3: Excelente (20 puntos) | V3: =VLOOKUP(TablaCalificaciones[[#This Row],[Metodología (nivel adecuado)]],PESOS!A$16:B$20,2,0) -> 20 | X3: Muy bueno (16 puntos) | Y3: =VLOOKUP(TablaCalificaciones[[#This Row],[Resultados y evidencia ]],PESOS!A$16:B$20,2,0) -> 16 | AA3: Excelente (10 puntos) | AB3: =VLOOKUP(TablaCalificaciones[[#This Row],[Coherencia y manejo del tiempo]],PESOS!A$25:B$29,2,0) -> 10 | AD3: Excelente (10 puntos) | AE3: =VLOOKUP(TablaCalificaciones[[#This Row],[Diapositivas como apoyo]],PESOS!A$25:B$29,2,0) -> 10 | AG3: Excelente (10 puntos) | AH3: =VLOOKUP(TablaCalificaciones[[#This Row],[Respuestas a preguntas]],PESOS!A$25:B$29,2,0) -> 10 | AJ3: Muy bueno (8 puntos) | AK3: =VLOOKUP(TablaCalificaciones[[#This Row],[Cierre: aporte a próximos pasos]],PESOS!A$25:B$29,2,0) -> 8
A4: 3 | B4: 46133.377 | C4: 46133.378 | D4: bernarda.sandoval@udla.edu.ec | E4: Bernarda Cecibel Sandoval | I4: Martes 21 | J4: 0 | L4: Bernarda Sandoval Romo | M4: =CONCATENATE(TablaCalificaciones[[#This Row],[Seleccione su nombre (Evaluador)]],TablaCalificaciones[[#This Row],[Seleccione el nombre del Estudiante]]) -> Bernarda Sandoval RomoGarate Pazmiño Víctor Adrián | O4: Garate Pazmiño Víctor Adrián | P4: 0 | R4: Excelente (20 puntos) | S4: =VLOOKUP(TablaCalificaciones[[#This Row],[Apertura: problema y objetivo ]],PESOS!A$16:B$20,2,0) -> 20 | U4: Excelente (20 puntos) | V4: =VLOOKUP(TablaCalificaciones[[#This Row],[Metodología (nivel adecuado)]],PESOS!A$16:B$20,2,0) -> 20 | X4: Muy bueno (16 puntos) | Y4: =VLOOKUP(TablaCalificaciones[[#This Row],[Resultados y evidencia ]],PESOS!A$16:B$20,2,0) -> 16 | AA4: Excelente (10 puntos) | AB4: =VLOOKUP(TablaCalificaciones[[#This Row],[Coherencia y manejo del tiempo]],PESOS!A$25:B$29,2,0) -> 10 | AD4: Excelente (10 puntos) | AE4: =VLOOKUP(TablaCalificaciones[[#This Row],[Diapositivas como apoyo]],PESOS!A$25:B$29,2,0) -> 10 | AG4: Excelente (10 puntos) | AH4: =VLOOKUP(TablaCalificaciones[[#This Row],[Respuestas a preguntas]],PESOS!A$25:B$29,2,0) -> 10 | AJ4: Muy bueno (8 puntos) | AK4: =VLOOKUP(TablaCalificaciones[[#This Row],[Cierre: aporte a próximos pasos]],PESOS!A$25:B$29,2,0) -> 8
A5: 4 | B5: 46133.378 | C5: 46133.379 | D5: bernarda.sandoval@udla.edu.ec | E5: Bernarda Cecibel Sandoval | I5: Martes 21 | J5: 0 | L5: Bernarda Sandoval Romo | M5: =CONCATENATE(TablaCalificaciones[[#This Row],[Seleccione su nombre (Evaluador)]],TablaCalificaciones[[#This Row],[Seleccione el nombre del Estudiante]]) -> Bernarda Sandoval RomoRueda Bravo Erick Josué | O5: Rueda Bravo Erick Josué | P5: 0 | R5: Excelente (20 puntos) | S5: =VLOOKUP(TablaCalificaciones[[#This Row],[Apertura: problema y objetivo ]],PESOS!A$16:B$20,2,0) -> 20 | U5: Excelente (20 puntos) | V5: =VLOOKUP(TablaCalificaciones[[#This Row],[Metodología (nivel adecuado)]],PESOS!A$16:B$20,2,0) -> 20 | X5: Muy bueno (16 puntos) | Y5: =VLOOKUP(TablaCalificaciones[[#This Row],[Resultados y evidencia ]],PESOS!A$16:B$20,2,0) -> 16 | AA5: Excelente (10 puntos) | AB5: =VLOOKUP(TablaCalificaciones[[#This Row],[Coherencia y manejo del tiempo]],PESOS!A$25:B$29,2,0) -> 10 | AD5: Excelente (10 puntos) | AE5: =VLOOKUP(TablaCalificaciones[[#This Row],[Diapositivas como apoyo]],PESOS!A$25:B$29,2,0) -> 10 | AG5: Excelente (10 puntos) | AH5: =VLOOKUP(TablaCalificaciones[[#This Row],[Respuestas a preguntas]],PESOS!A$25:B$29,2,0) -> 10 | AJ5: Muy bueno (8 puntos) | AK5: =VLOOKUP(TablaCalificaciones[[#This Row],[Cierre: aporte a próximos pasos]],PESOS!A$25:B$29,2,0) -> 8
A6: 5 | B6: 46133.383 | C6: 46133.385 | D6: marco.galarza@udla.edu.ec | E6: Marco Galarza | I6: Martes 21 | J6: 0 | L6: Marco Antonio Galarza Castillo | M6: =CONCATENATE(TablaCalificaciones[[#This Row],[Seleccione su nombre (Evaluador)]],TablaCalificaciones[[#This Row],[Seleccione el nombre del Estudiante]]) -> Marco Antonio Galarza CastilloCalderón Tuárez Diana Alejandra | O6: Calderón Tuárez Diana Alejandra | P6: 0 | R6: Excelente (20 puntos) | S6: =VLOOKUP(TablaCalificaciones[[#This Row],[Apertura: problema y objetivo ]],PESOS!A$16:B$20,2,0) -> 20 | U6: Excelente (20 puntos) | V6: =VLOOKUP(TablaCalificaciones[[#This Row],[Metodología (nivel adecuado)]],PESOS!A$16:B$20,2,0) -> 20 | X6: Excelente (20 puntos) | Y6: =VLOOKUP(TablaCalificaciones[[#This Row],[Resultados y evidencia ]],PESOS!A$16:B$20,2,0) -> 20 | AA6: Muy bueno (8 puntos) | AB6: =VLOOKUP(TablaCalificaciones[[#This Row],[Coherencia y manejo del tiempo]],PESOS!A$25:B$29,2,0) -> 8 | AD6: Excelente (10 puntos) | AE6: =VLOOKUP(TablaCalificaciones[[#This Row],[Diapositivas como apoyo]],PESOS!A$25:B$29,2,0) -> 10 | AG6: Muy bueno (8 puntos) | AH6: =VLOOKUP(TablaCalificaciones[[#This Row],[Respuestas a preguntas]],PESOS!A$25:B$29,2,0) -> 8 | AJ6: Excelente (10 puntos) | AK6: =VLOOKUP(TablaCalificaciones[[#This Row],[Cierre: aporte a próximos pasos]],PESOS!A$25:B$29,2,0) -> 10
A7: 6 | B7: 46133.385 | C7: 46133.385 | D7: marco.galarza@udla.edu.ec | E7: Marco Galarza | I7: Martes 21 | J7: 0 | L7: Marco Antonio Galarza Castillo | M7: =CONCATENATE(TablaCalificaciones[[#This Row],[Seleccione su nombre (Evaluador)]],TablaCalificaciones[[#This Row],[Seleccione el nombre del Estudiante]]) -> Marco Antonio Galarza CastilloMartínez Porte Carlos Sebastián | O7: Martínez Porte Carlos Sebastián | P7: 0 | R7: Excelente (20 puntos) | S7: =VLOOKUP(TablaCalificaciones[[#This Row],[Apertura: problema y objetivo ]],PESOS!A$16:B$20,2,0) -> 20 | U7: Excelente (20 puntos) | V7: =VLOOKUP(TablaCalificaciones[[#This Row],[Metodología (nivel adecuado)]],PESOS!A$16:B$20,2,0) -> 20 | X7: Excelente (20 puntos) | Y7: =VLOOKUP(TablaCalificaciones[[#This Row],[Resultados y evidencia ]],PESOS!A$16:B$20,2,0) -> 20 | AA7: Muy bueno (8 puntos) | AB7: =VLOOKUP(TablaCalificaciones[[#This Row],[Coherencia y manejo del tiempo]],PESOS!A$25:B$29,2,0) -> 8 | AD7: Excelente (10 puntos) | AE7: =VLOOKUP(TablaCalificaciones[[#This Row],[Diapositivas como apoyo]],PESOS!A$25:B$29,2,0) -> 10 | AG7: Muy bueno (8 puntos) | AH7: =VLOOKUP(TablaCalificaciones[[#This Row],[Respuestas a preguntas]],PESOS!A$25:B$29,2,0) -> 8 | AJ7: Excelente (10 puntos) | AK7: =VLOOKUP(TablaCalificaciones[[#This Row],[Cierre: aporte a próximos pasos]],PESOS!A$25:B$29,2,0) -> 10
A8: 7 | B8: 46133.385 | C8: 46133.386 | D8: marco.galarza@udla.edu.ec | E8: Marco Galarza | I8: Martes 21 | J8: 0 | L8: Marco Antonio Galarza Castillo | M8: =CONCATENATE(TablaCalificaciones[[#This Row],[Seleccione su nombre (Evaluador)]],TablaCalificaciones[[#This Row],[Seleccione el nombre del Estudiante]]) -> Marco Antonio Galarza CastilloSolano De La Sala Aldas Paúl Fernando | O8: Solano De La Sala Aldas Paúl Fernando | P8: 0 | R8: Excelente (20 puntos) | S8: =VLOOKUP(TablaCalificaciones[[#This Row],[Apertura: problema y objetivo ]],PESOS!A$16:B$20,2,0) -> 20 | U8: Excelente (20 puntos) | V8: =VLOOKUP(TablaCalificaciones[[#This Row],[Metodología (nivel adecuado)]],PESOS!A$16:B$20,2,0) -> 20 | X8: Excelente (20 puntos) | Y8: =VLOOKUP(TablaCalificaciones[[#This Row],[Resultados y evidencia ]],PESOS!A$16:B$20,2,0) -> 20 | AA8: Muy bueno (8 puntos) | AB8: =VLOOKUP(TablaCalificaciones[[#This Row],[Coherencia y manejo del tiempo]],PESOS!A$25:B$29,2,0) -> 8 | AD8: Excelente (10 puntos) | AE8: =VLOOKUP(TablaCalificaciones[[#This Row],[Diapositivas como apoyo]],PESOS!A$25:B$29,2,0) -> 10 | AG8: Excelente (10 puntos) | AH8: =VLOOKUP(TablaCalificaciones[[#This Row],[Respuestas a preguntas]],PESOS!A$25:B$29,2,0) -> 10 | AJ8: Excelente (10 puntos) | AK8: =VLOOKUP(TablaCalificaciones[[#This Row],[Cierre: aporte a próximos pasos]],PESOS!A$25:B$29,2,0) -> 10
A9: 8 | B9: 46133.376 | C9: 46133.397 | D9: santiago.solorzano@udla.edu.ec | E9: Santiago Leonardo Solórzano | I9: Martes 21 | J9: 0 | L9: Santiago Leonardo Solórzano | M9: =CONCATENATE(TablaCalificaciones[[#This Row],[Seleccione su nombre (Evaluador)]],TablaCalificaciones[[#This Row],[Seleccione el nombre del Estudiante]]) -> Santiago Leonardo SolórzanoVinueza Torres Luis Fernando | O9: Vinueza Torres Luis Fernando | P9: 0 | R9: Excelente (20 puntos) | S9: =VLOOKUP(TablaCalificaciones[[#This Row],[Apertura: problema y objetivo ]],PESOS!A$16:B$20,2,0) -> 20 | U9: Excelente (20 puntos) | V9: =VLOOKUP(TablaCalificaciones[[#This Row],[Metodología (nivel adecuado)]],PESOS!A$16:B$20,2,0) -> 20 | X9: Excelente (20 puntos) | Y9: =VLOOKUP(TablaCalificaciones[[#This Row],[Resultados y evidencia ]],PESOS!A$16:B$20,2,0) -> 20 | AA9: Muy bueno (8 puntos) | AB9: =VLOOKUP(TablaCalificaciones[[#This Row],[Coherencia y manejo del tiempo]],PESOS!A$25:B$29,2,0) -> 8 | AD9: Muy bueno (8 puntos) | AE9: =VLOOKUP(TablaCalificaciones[[#This Row],[Diapositivas como apoyo]],PESOS!A$25:B$29,2,0) -> 8 | AG9: Muy bueno (8 puntos) | AH9: =VLOOKUP(TablaCalificaciones[[#This Row],[Respuestas a preguntas]],PESOS!A$25:B$29,2,0) -> 8 | AJ9: Excelente (10 puntos) | AK9: =VLOOKUP(TablaCalificaciones[[#This Row],[Cierre: aporte a próximos pasos]],PESOS!A$25:B$29,2,0) -> 10
A10: 9 | B10: 46133.002 | C10: 46133.397 | D10: santiago.solorzano@udla.edu.ec | E10: Santiago Leonardo Solórzano | I10: Martes 21 | J10: 0 | L10: Santiago Leonardo Solórzano | M10: =CONCATENATE(TablaCalificaciones[[#This Row],[Seleccione su nombre (Evaluador)]],TablaCalificaciones[[#This Row],[Seleccione el nombre del Estudiante]]) -> Santiago Leonardo SolórzanoRedin Muñoz Juan Sebastián | O10: Redin Muñoz Juan Sebastián | P10: 0 | R10: Excelente (20 puntos) | S10: =VLOOKUP(TablaCalificaciones[[#This Row],[Apertura: problema y objetivo ]],PESOS!A$16:B$20,2,0) -> 20 | U10: Excelente (20 puntos) | V10: =VLOOKUP(TablaCalificaciones[[#This Row],[Metodología (nivel adecuado)]],PESOS!A$16:B$20,2,0) -> 20 | X10: Excelente (20 puntos) | Y10: =VLOOKUP(TablaCalificaciones[[#This Row],[Resultados y evidencia ]],PESOS!A$16:B$20,2,0) -> 20 | AA10: Muy bueno (8 puntos) | AB10: =VLOOKUP(TablaCalificaciones[[#This Row],[Coherencia y manejo del tiempo]],PESOS!A$25:B$29,2,0) -> 8 | AD10: Muy bueno (8 puntos) | AE10: =VLOOKUP(TablaCalificaciones[[#This Row],[Diapositivas como apoyo]],PESOS!A$25:B$29,2,0) -> 8 | AG10: Muy bueno (8 puntos) | AH10: =VLOOKUP(TablaCalificaciones[[#This Row],[Respuestas a preguntas]],PESOS!A$25:B$29,2,0) -> 8 | AJ10: Excelente (10 puntos) | AK10: =VLOOKUP(TablaCalificaciones[[#This Row],[Cierre: aporte a próximos pasos]],PESOS!A$25:B$29,2,0) -> 10
A11: 10 | B11: 46133.386 | C11: 46133.4 | D11: marco.galarza@udla.edu.ec | E11: Marco Galarza | I11: Martes 21 | J11: 0 | L11: Marco Antonio Galarza Castillo | M11: =CONCATENATE(TablaCalificaciones[[#This Row],[Seleccione su nombre (Evaluador)]],TablaCalificaciones[[#This Row],[Seleccione el nombre del Estudiante]]) -> Marco Antonio Galarza CastilloFernández Lazcano María José | O11: Fernández Lazcano María José | P11: 0 | R11: Excelente (20 puntos) | S11: =VLOOKUP(TablaCalificaciones[[#This Row],[Apertura: problema y objetivo ]],PESOS!A$16:B$20,2,0) -> 20 | U11: Excelente (20 puntos) | V11: =VLOOKUP(TablaCalificaciones[[#This Row],[Metodología (nivel adecuado)]],PESOS!A$16:B$20,2,0) -> 20 | X11: Excelente (20 puntos) | Y11: =VLOOKUP(TablaCalificaciones[[#This Row],[Resultados y evidencia ]],PESOS!A$16:B$20,2,0) -> 20 | AA11: Excelente (10 puntos) | AB11: =VLOOKUP(TablaCalificaciones[[#This Row],[Coherencia y manejo del tiempo]],PESOS!A$25:B$29,2,0) -> 10 | AD11: Excelente (10 puntos) | AE11: =VLOOKUP(TablaCalificaciones[[#This Row],[Diapositivas como apoyo]],PESOS!A$25:B$29,2,0) -> 10 | AG11: Excelente (10 puntos) | AH11: =VLOOKUP(TablaCalificaciones[[#This Row],[Respuestas a preguntas]],PESOS!A$25:B$29,2,0) -> 10 | AJ11: Excelente (10 puntos) | AK11: =VLOOKUP(TablaCalificaciones[[#This Row],[Cierre: aporte a próximos pasos]],PESOS!A$25:B$29,2,0) -> 10
A12: 11 | B12: 46133.4 | C12: 46133.4 | D12: marco.galarza@udla.edu.ec | E12: Marco Galarza | I12: Martes 21 | J12: 0 | L12: Marco Antonio Galarza Castillo | M12: =CONCATENATE(TablaCalificaciones[[#This Row],[Seleccione su nombre (Evaluador)]],TablaCalificaciones[[#This Row],[Seleccione el nombre del Estudiante]]) -> Marco Antonio Galarza CastilloSacoto Macías Alicia Fernanda | O12: Sacoto Macías Alicia Fernanda | P12: 0 | R12: Excelente (20 puntos) | S12: =VLOOKUP(TablaCalificaciones[[#This Row],[Apertura: problema y objetivo ]],PESOS!A$16:B$20,2,0) -> 20 | U12: Excelente (20 puntos) | V12: =VLOOKUP(TablaCalificaciones[[#This Row],[Metodología (nivel adecuado)]],PESOS!A$16:B$20,2,0) -> 20 | X12: Excelente (20 puntos) | Y12: =VLOOKUP(TablaCalificaciones[[#This Row],[Resultados y evidencia ]],PESOS!A$16:B$20,2,0) -> 20 | AA12: Excelente (10 puntos) | AB12: =VLOOKUP(TablaCalificaciones[[#This Row],[Coherencia y manejo del tiempo]],PESOS!A$25:B$29,2,0) -> 10 | AD12: Excelente (10 puntos) | AE12: =VLOOKUP(TablaCalificaciones[[#This Row],[Diapositivas como apoyo]],PESOS!A$25:B$29,2,0) -> 10 | AG12: Excelente (10 puntos) | AH12: =VLOOKUP(TablaCalificaciones[[#This Row],[Respuestas a preguntas]],PESOS!A$25:B$29,2,0) -> 10 | AJ12: Excelente (10 puntos) | AK12: =VLOOKUP(TablaCalificaciones[[#This Row],[Cierre: aporte a próximos pasos]],PESOS!A$25:B$29,2,0) -> 10
A13: 12 | B13: 46133.4 | C13: 46133.4 | D13: marco.galarza@udla.edu.ec | E13: Marco Galarza | I13: Martes 21 | J13: 0 | L13: Marco Antonio Galarza Castillo | M13: =CONCATENATE(TablaCalificaciones[[#This Row],[Seleccione su nombre (Evaluador)]],TablaCalificaciones[[#This Row],[Seleccione el nombre del Estudiante]]) -> Marco Antonio Galarza CastilloZaldumbide Egas Ana Cristina | O13: Zaldumbide Egas Ana Cristina | P13: 0 | R13: Excelente (20 puntos) | S13: =VLOOKUP(TablaCalificaciones[[#This Row],[Apertura: problema y objetivo ]],PESOS!A$16:B$20,2,0) -> 20 | U13: Excelente (20 puntos) | V13: =VLOOKUP(TablaCalificaciones[[#This Row],[Metodología (nivel adecuado)]],PESOS!A$16:B$20,2,0) -> 20 | X13: Excelente (20 puntos) | Y13: =VLOOKUP(TablaCalificaciones[[#This Row],[Resultados y evidencia ]],PESOS!A$16:B$20,2,0) -> 20 | AA13: Excelente (10 puntos) | AB13: =VLOOKUP(TablaCalificaciones[[#This Row],[Coherencia y manejo del tiempo]],PESOS!A$25:B$29,2,0) -> 10 | AD13: Excelente (10 puntos) | AE13: =VLOOKUP(TablaCalificaciones[[#This Row],[Diapositivas como apoyo]],PESOS!A$25:B$29,2,0) -> 10 | AG13: Excelente (10 puntos) | AH13: =VLOOKUP(TablaCalificaciones[[#This Row],[Respuestas a preguntas]],PESOS!A$25:B$29,2,0) -> 10 | AJ13: Excelente (10 puntos) | AK13: =VLOOKUP(TablaCalificaciones[[#This Row],[Cierre: aporte a próximos pasos]],PESOS!A$25:B$29,2,0) -> 10
... A101: 100 | B101: 46133.526 | C101: 46133.533 | D101: santiago.solorzano@udla.edu.ec | E101: Santiago Leonardo Solórzano | I101: Martes 21 | J101: 0 | L101: Santiago Leonardo Solórzano | M101: =CONCATENATE(TablaCalificaciones[[#This Row],[Seleccione su nombre (Evaluador)]],TablaCalificaciones[[#This Row],[Seleccione el nombre del Estudiante]]) -> Santiago Leonardo SolórzanoVargas Moreira Marcela Sheccid | O101: Vargas Moreira Marcela Sheccid | P101: 0 | R101: Excelente (20 puntos) | S101: =VLOOKUP(TablaCalificaciones[[#This Row],[Apertura: problema y objetivo ]],PESOS!A$16:B$20,2,0) -> 20 | U101: Excelente (20 puntos) | V101: =VLOOKUP(TablaCalificaciones[[#This Row],[Metodología (nivel adecuado)]],PESOS!A$16:B$20,2,0) -> 20 | X101: Excelente (20 puntos) | Y101: =VLOOKUP(TablaCalificaciones[[#This Row],[Resultados y evidencia ]],PESOS!A$16:B$20,2,0) -> 20 | AA101: Excelente (10 puntos) | AB101: =VLOOKUP(TablaCalificaciones[[#This Row],[Coherencia y manejo del tiempo]],PESOS!A$25:B$29,2,0) -> 10 | AD101: Muy bueno (8 puntos) | AE101: =VLOOKUP(TablaCalificaciones[[#This Row],[Diapositivas como apoyo]],PESOS!A$25:B$29,2,0) -> 8 | AG101: Excelente (10 puntos) | AH101: =VLOOKUP(TablaCalificaciones[[#This Row],[Respuestas a preguntas]],PESOS!A$25:B$29,2,0) -> 10 | AJ101: Excelente (10 puntos) | AK101: =VLOOKUP(TablaCalificaciones[[#This Row],[Cierre: aporte a próximos pasos]],PESOS!A$25:B$29,2,0) -> 10
A102: 101 | B102: 46133.527 | C102: 46133.533 | D102: santiago.solorzano@udla.edu.ec | E102: Santiago Leonardo Solórzano | I102: Martes 21 | L102: Santiago Leonardo Solórzano | M102: =CONCATENATE(TablaCalificaciones[[#This Row],[Seleccione su nombre (Evaluador)]],TablaCalificaciones[[#This Row],[Seleccione el nombre del Estudiante]]) -> Santiago Leonardo SolórzanoVillavicencio Quiñonez Alex Santiago | O102: Villavicencio Quiñonez Alex Santiago | R102: Excelente (20 puntos) | S102: =VLOOKUP(TablaCalificaciones[[#This Row],[Apertura: problema y objetivo ]],PESOS!A$16:B$20,2,0) -> 20 | U102: Excelente (20 puntos) | V102: =VLOOKUP(TablaCalificaciones[[#This Row],[Metodología (nivel adecuado)]],PESOS!A$16:B$20,2,0) -> 20 | X102: Excelente (20 puntos) | Y102: =VLOOKUP(TablaCalificaciones[[#This Row],[Resultados y evidencia ]],PESOS!A$16:B$20,2,0) -> 20 | AA102: Excelente (10 puntos) | AB102: =VLOOKUP(TablaCalificaciones[[#This Row],[Coherencia y manejo del tiempo]],PESOS!A$25:B$29,2,0) -> 10 | AD102: Muy bueno (8 puntos) | AE102: =VLOOKUP(TablaCalificaciones[[#This Row],[Diapositivas como apoyo]],PESOS!A$25:B$29,2,0) -> 8 | AG102: Excelente (10 puntos) | AH102: =VLOOKUP(TablaCalificaciones[[#This Row],[Respuestas a preguntas]],PESOS!A$25:B$29,2,0) -> 10 | AJ102: Excelente (10 puntos) | AK102: =VLOOKUP(TablaCalificaciones[[#This Row],[Cierre: aporte a próximos pasos]],PESOS!A$25:B$29,2,0) -> 10
A103: 102 | B103: 46133.533 | C103: 46133.536 | D103: ana.tulcanaza@udla.edu.ec | E103: Ana Belen Tulcanaza | I103: Martes 21 | L103: Ana Belén Tulcanaza Prieto | M103: =CONCATENATE(TablaCalificaciones[[#This Row],[Seleccione su nombre (Evaluador)]],TablaCalificaciones[[#This Row],[Seleccione el nombre del Estudiante]]) -> Ana Belén Tulcanaza PrietoArmas Torres Diego Sebastian | O103: Armas Torres Diego Sebastian | R103: Excelente (20 puntos) | S103: =VLOOKUP(TablaCalificaciones[[#This Row],[Apertura: problema y objetivo ]],PESOS!A$16:B$20,2,0) -> 20 | U103: Excelente (20 puntos) | V103: =VLOOKUP(TablaCalificaciones[[#This Row],[Metodología (nivel adecuado)]],PESOS!A$16:B$20,2,0) -> 20 | X103: Excelente (20 puntos) | Y103: =VLOOKUP(TablaCalificaciones[[#This Row],[Resultados y evidencia ]],PESOS!A$16:B$20,2,0) -> 20 | AA103: Excelente (10 puntos) | AB103: =VLOOKUP(TablaCalificaciones[[#This Row],[Coherencia y manejo del tiempo]],PESOS!A$25:B$29,2,0) -> 10 | AD103: Excelente (10 puntos) | AE103: =VLOOKUP(TablaCalificaciones[[#This Row],[Diapositivas como apoyo]],PESOS!A$25:B$29,2,0) -> 10 | AG103: Excelente (10 puntos) | AH103: =VLOOKUP(TablaCalificaciones[[#This Row],[Respuestas a preguntas]],PESOS!A$25:B$29,2,0) -> 10 | AJ103: Excelente (10 puntos) | AK103: =VLOOKUP(TablaCalificaciones[[#This Row],[Cierre: aporte a próximos pasos]],PESOS!A$25:B$29,2,0) -> 10
A104: 103 | B104: 46133.533 | C104: 46133.536 | D104: ana.tulcanaza@udla.edu.ec | E104: Ana Belen Tulcanaza | I104: Martes 21 | L104: Ana Belén Tulcanaza Prieto | M104: =CONCATENATE(TablaCalificaciones[[#This Row],[Seleccione su nombre (Evaluador)]],TablaCalificaciones[[#This Row],[Seleccione el nombre del Estudiante]]) -> Ana Belén Tulcanaza PrietoVargas Moreira Marcela Sheccid | O104: Vargas Moreira Marcela Sheccid | R104: Excelente (20 puntos) | S104: =VLOOKUP(TablaCalificaciones[[#This Row],[Apertura: problema y objetivo ]],PESOS!A$16:B$20,2,0) -> 20 | U104: Excelente (20 puntos) | V104: =VLOOKUP(TablaCalificaciones[[#This Row],[Metodología (nivel adecuado)]],PESOS!A$16:B$20,2,0) -> 20 | X104: Excelente (20 puntos) | Y104: =VLOOKUP(TablaCalificaciones[[#This Row],[Resultados y evidencia ]],PESOS!A$16:B$20,2,0) -> 20 | AA104: Excelente (10 puntos) | AB104: =VLOOKUP(TablaCalificaciones[[#This Row],[Coherencia y manejo del tiempo]],PESOS!A$25:B$29,2,0) -> 10 | AD104: Excelente (10 puntos) | AE104: =VLOOKUP(TablaCalificaciones[[#This Row],[Diapositivas como apoyo]],PESOS!A$25:B$29,2,0) -> 10 | AG104: Excelente (10 puntos) | AH104: =VLOOKUP(TablaCalificaciones[[#This Row],[Respuestas a preguntas]],PESOS!A$25:B$29,2,0) -> 10 | AJ104: Excelente (10 puntos) | AK104: =VLOOKUP(TablaCalificaciones[[#This Row],[Cierre: aporte a próximos pasos]],PESOS!A$25:B$29,2,0) -> 10
A105: 104 | B105: 46133.533 | C105: 46133.536 | D105: ana.tulcanaza@udla.edu.ec | E105: Ana Belen Tulcanaza | I105: Martes 21 | L105: Ana Belén Tulcanaza Prieto | M105: =CONCATENATE(TablaCalificaciones[[#This Row],[Seleccione su nombre (Evaluador)]],TablaCalificaciones[[#This Row],[Seleccione el nombre del Estudiante]]) -> Ana Belén Tulcanaza PrietoVillavicencio Quiñonez Alex Santiago | O105: Villavicencio Quiñonez Alex Santiago | R105: Excelente (20 puntos) | S105: =VLOOKUP(TablaCalificaciones[[#This Row],[Apertura: problema y objetivo ]],PESOS!A$16:B$20,2,0) -> 20 | U105: Excelente (20 puntos) | V105: =VLOOKUP(TablaCalificaciones[[#This Row],[Metodología (nivel adecuado)]],PESOS!A$16:B$20,2,0) -> 20 | X105: Excelente (20 puntos) | Y105: =VLOOKUP(TablaCalificaciones[[#This Row],[Resultados y evidencia ]],PESOS!A$16:B$20,2,0) -> 20 | AA105: Excelente (10 puntos) | AB105: =VLOOKUP(TablaCalificaciones[[#This Row],[Coherencia y manejo del tiempo]],PESOS!A$25:B$29,2,0) -> 10 | AD105: Excelente (10 puntos) | AE105: =VLOOKUP(TablaCalificaciones[[#This Row],[Diapositivas como apoyo]],PESOS!A$25:B$29,2,0) -> 10 | AG105: Excelente (10 puntos) | AH105: =VLOOKUP(TablaCalificaciones[[#This Row],[Respuestas a preguntas]],PESOS!A$25:B$29,2,0) -> 10 | AJ105: Excelente (10 puntos) | AK105: =VLOOKUP(TablaCalificaciones[[#This Row],[Cierre: aporte a próximos pasos]],PESOS!A$25:B$29,2,0) -> 10
A106: 105 | B106: 46133.516 | C106: 46133.537 | D106: marco.galarza@udla.edu.ec | E106: Marco Galarza | I106: Martes 21 | L106: Marco Antonio Galarza Castillo | M106: =CONCATENATE(TablaCalificaciones[[#This Row],[Seleccione su nombre (Evaluador)]],TablaCalificaciones[[#This Row],[Seleccione el nombre del Estudiante]]) -> Marco Antonio Galarza CastilloGaleas Andino Marco Vinicio | O106: Galeas Andino Marco Vinicio | R106: Excelente (20 puntos) | S106: =VLOOKUP(TablaCalificaciones[[#This Row],[Apertura: problema y objetivo ]],PESOS!A$16:B$20,2,0) -> 20 | U106: Excelente (20 puntos) | V106: =VLOOKUP(TablaCalificaciones[[#This Row],[Metodología (nivel adecuado)]],PESOS!A$16:B$20,2,0) -> 20 | X106: Excelente (20 puntos) | Y106: =VLOOKUP(TablaCalificaciones[[#This Row],[Resultados y evidencia ]],PESOS!A$16:B$20,2,0) -> 20 | AA106: Excelente (10 puntos) | AB106: =VLOOKUP(TablaCalificaciones[[#This Row],[Coherencia y manejo del tiempo]],PESOS!A$25:B$29,2,0) -> 10 | AD106: Excelente (10 puntos) | AE106: =VLOOKUP(TablaCalificaciones[[#This Row],[Diapositivas como apoyo]],PESOS!A$25:B$29,2,0) -> 10 | AG106: Excelente (10 puntos) | AH106: =VLOOKUP(TablaCalificaciones[[#This Row],[Respuestas a preguntas]],PESOS!A$25:B$29,2,0) -> 10 | AJ106: Excelente (10 puntos) | AK106: =VLOOKUP(TablaCalificaciones[[#This Row],[Cierre: aporte a próximos pasos]],PESOS!A$25:B$29,2,0) -> 10
A107: 106 | B107: 46133.536 | C107: 46133.538 | D107: patricia.acosta@udla.edu.ec | E107: Patricia Acosta | I107: Martes 21 | L107: Nelly Patricia Acosta Vargas | M107: =CONCATENATE(TablaCalificaciones[[#This Row],[Seleccione su nombre (Evaluador)]],TablaCalificaciones[[#This Row],[Seleccione el nombre del Estudiante]]) -> Nelly Patricia Acosta VargasGaleas Andino Marco Vinicio | O107: Galeas Andino Marco Vinicio | R107: Excelente (20 puntos) | S107: =VLOOKUP(TablaCalificaciones[[#This Row],[Apertura: problema y objetivo ]],PESOS!A$16:B$20,2,0) -> 20 | U107: Excelente (20 puntos) | V107: =VLOOKUP(TablaCalificaciones[[#This Row],[Metodología (nivel adecuado)]],PESOS!A$16:B$20,2,0) -> 20 | X107: Excelente (20 puntos) | Y107: =VLOOKUP(TablaCalificaciones[[#This Row],[Resultados y evidencia ]],PESOS!A$16:B$20,2,0) -> 20 | AA107: Excelente (10 puntos) | AB107: =VLOOKUP(TablaCalificaciones[[#This Row],[Coherencia y manejo del tiempo]],PESOS!A$25:B$29,2,0) -> 10 | AD107: Excelente (10 puntos) | AE107: =VLOOKUP(TablaCalificaciones[[#This Row],[Diapositivas como apoyo]],PESOS!A$25:B$29,2,0) -> 10 | AG107: Excelente (10 puntos) | AH107: =VLOOKUP(TablaCalificaciones[[#This Row],[Respuestas a preguntas]],PESOS!A$25:B$29,2,0) -> 10 | AJ107: Excelente (10 puntos) | AK107: =VLOOKUP(TablaCalificaciones[[#This Row],[Cierre: aporte a próximos pasos]],PESOS!A$25:B$29,2,0) -> 10
A108: 107 | B108: 46133.542 | C108: 46133.548 | D108: patricia.acosta@udla.edu.ec | E108: Patricia Acosta | I108: Martes 21 | L108: Nelly Patricia Acosta Vargas | M108: =CONCATENATE(TablaCalificaciones[[#This Row],[Seleccione su nombre (Evaluador)]],TablaCalificaciones[[#This Row],[Seleccione el nombre del Estudiante]]) -> Nelly Patricia Acosta VargasCalderón Saravia Alex Javier | O108: Calderón Saravia Alex Javier | R108: Excelente (20 puntos) | S108: =VLOOKUP(TablaCalificaciones[[#This Row],[Apertura: problema y objetivo ]],PESOS!A$16:B$20,2,0) -> 20 | U108: Excelente (20 puntos) | V108: =VLOOKUP(TablaCalificaciones[[#This Row],[Metodología (nivel adecuado)]],PESOS!A$16:B$20,2,0) -> 20 | X108: Excelente (20 puntos) | Y108: =VLOOKUP(TablaCalificaciones[[#This Row],[Resultados y evidencia ]],PESOS!A$16:B$20,2,0) -> 20 | AA108: Excelente (10 puntos) | AB108: =VLOOKUP(TablaCalificaciones[[#This Row],[Coherencia y manejo del tiempo]],PESOS!A$25:B$29,2,0) -> 10 | AD108: Excelente (10 puntos) | AE108: =VLOOKUP(TablaCalificaciones[[#This Row],[Diapositivas como apoyo]],PESOS!A$25:B$29,2,0) -> 10 | AG108: Excelente (10 puntos) | AH108: =VLOOKUP(TablaCalificaciones[[#This Row],[Respuestas a preguntas]],PESOS!A$25:B$29,2,0) -> 10 | AJ108: Excelente (10 puntos) | AK108: =VLOOKUP(TablaCalificaciones[[#This Row],[Cierre: aporte a próximos pasos]],PESOS!A$25:B$29,2,0) -> 10
A109: 108 | B109: 46133.548 | C109: 46133.549 | D109: patricia.acosta@udla.edu.ec | E109: Patricia Acosta | I109: Martes 21 | L109: Nelly Patricia Acosta Vargas | M109: =CONCATENATE(TablaCalificaciones[[#This Row],[Seleccione su nombre (Evaluador)]],TablaCalificaciones[[#This Row],[Seleccione el nombre del Estudiante]]) -> Nelly Patricia Acosta VargasLincango Ninahualpa Pablo Andrés | O109: Lincango Ninahualpa Pablo Andrés | R109: Excelente (20 puntos) | S109: =VLOOKUP(TablaCalificaciones[[#This Row],[Apertura: problema y objetivo ]],PESOS!A$16:B$20,2,0) -> 20 | U109: Excelente (20 puntos) | V109: =VLOOKUP(TablaCalificaciones[[#This Row],[Metodología (nivel adecuado)]],PESOS!A$16:B$20,2,0) -> 20 | X109: Excelente (20 puntos) | Y109: =VLOOKUP(TablaCalificaciones[[#This Row],[Resultados y evidencia ]],PESOS!A$16:B$20,2,0) -> 20 | AA109: Excelente (10 puntos) | AB109: =VLOOKUP(TablaCalificaciones[[#This Row],[Coherencia y manejo del tiempo]],PESOS!A$25:B$29,2,0) -> 10 | AD109: Excelente (10 puntos) | AE109: =VLOOKUP(TablaCalificaciones[[#This Row],[Diapositivas como apoyo]],PESOS!A$25:B$29,2,0) -> 10 | AG109: Excelente (10 puntos) | AH109: =VLOOKUP(TablaCalificaciones[[#This Row],[Respuestas a preguntas]],PESOS!A$25:B$29,2,0) -> 10 | AJ109: Excelente (10 puntos) | AK109: =VLOOKUP(TablaCalificaciones[[#This Row],[Cierre: aporte a próximos pasos]],PESOS!A$25:B$29,2,0) -> 10
A110: 109 | B110: 46133.549 | C110: 46133.553 | D110: patricia.acosta@udla.edu.ec | E110: Patricia Acosta | I110: Martes 21 | L110: Nelly Patricia Acosta Vargas | M110: =CONCATENATE(TablaCalificaciones[[#This Row],[Seleccione su nombre (Evaluador)]],TablaCalificaciones[[#This Row],[Seleccione el nombre del Estudiante]]) -> Nelly Patricia Acosta VargasCabrera Santamaría Jimena Marcela | O110: Cabrera Santamaría Jimena Marcela | R110: Excelente (20 puntos) | S110: =VLOOKUP(TablaCalificaciones[[#This Row],[Apertura: problema y objetivo ]],PESOS!A$16:B$20,2,0) -> 20 | U110: Excelente (20 puntos) | V110: =VLOOKUP(TablaCalificaciones[[#This Row],[Metodología (nivel adecuado)]],PESOS!A$16:B$20,2,0) -> 20 | X110: Excelente (20 puntos) | Y110: =VLOOKUP(TablaCalificaciones[[#This Row],[Resultados y evidencia ]],PESOS!A$16:B$20,2,0) -> 20 | AA110: Excelente (10 puntos) | AB110: =VLOOKUP(TablaCalificaciones[[#This Row],[Coherencia y manejo del tiempo]],PESOS!A$25:B$29,2,0) -> 10 | AD110: Excelente (10 puntos) | AE110: =VLOOKUP(TablaCalificaciones[[#This Row],[Diapositivas como apoyo]],PESOS!A$25:B$29,2,0) -> 10 | AG110: Excelente (10 puntos) | AH110: =VLOOKUP(TablaCalificaciones[[#This Row],[Respuestas a preguntas]],PESOS!A$25:B$29,2,0) -> 10 | AJ110: Excelente (10 puntos) | AK110: =VLOOKUP(TablaCalificaciones[[#This Row],[Cierre: aporte a próximos pasos]],PESOS!A$25:B$29,2,0) -> 10
A111: 110 | B111: 46133.538 | C111: 46133.559 | D111: santiago.solorzano@udla.edu.ec | E111: Santiago Leonardo Solórzano | I111: Martes 21 | L111: Santiago Leonardo Solórzano | M111: =CONCATENATE(TablaCalificaciones[[#This Row],[Seleccione su nombre (Evaluador)]],TablaCalificaciones[[#This Row],[Seleccione el nombre del Estudiante]]) -> Santiago Leonardo SolórzanoBeltrán Basantes Oscar Omar | O111: Beltrán Basantes Oscar Omar | R111: Excelente (20 puntos) | S111: =VLOOKUP(TablaCalificaciones[[#This Row],[Apertura: problema y objetivo ]],PESOS!A$16:B$20,2,0) -> 20 | U111: Excelente (20 puntos) | V111: =VLOOKUP(TablaCalificaciones[[#This Row],[Metodología (nivel adecuado)]],PESOS!A$16:B$20,2,0) -> 20 | X111: Excelente (20 puntos) | Y111: =VLOOKUP(TablaCalificaciones[[#This Row],[Resultados y evidencia ]],PESOS!A$16:B$20,2,0) -> 20 | AA111: Excelente (10 puntos) | AB111: =VLOOKUP(TablaCalificaciones[[#This Row],[Coherencia y manejo del tiempo]],PESOS!A$25:B$29,2,0) -> 10 | AD111: Excelente (10 puntos) | AE111: =VLOOKUP(TablaCalificaciones[[#This Row],[Diapositivas como apoyo]],PESOS!A$25:B$29,2,0) -> 10 | AG111: Excelente (10 puntos) | AH111: =VLOOKUP(TablaCalificaciones[[#This Row],[Respuestas a preguntas]],PESOS!A$25:B$29,2,0) -> 10 | AJ111: Excelente (10 puntos) | AK111: =VLOOKUP(TablaCalificaciones[[#This Row],[Cierre: aporte a próximos pasos]],PESOS!A$25:B$29,2,0) -> 10
A112: 111 | B112: 46133.538 | C112: 46133.559 | D112: santiago.solorzano@udla.edu.ec | E112: Santiago Leonardo Solórzano | I112: Martes 21 | L112: Santiago Leonardo Solórzano | M112: =CONCATENATE(TablaCalificaciones[[#This Row],[Seleccione su nombre (Evaluador)]],TablaCalificaciones[[#This Row],[Seleccione el nombre del Estudiante]]) -> Santiago Leonardo SolórzanoPazmiño Carrera Sonia Lucia | O112: Pazmiño Carrera Sonia Lucia | R112: Excelente (20 puntos) | S112: =VLOOKUP(TablaCalificaciones[[#This Row],[Apertura: problema y objetivo ]],PESOS!A$16:B$20,2,0) -> 20 | U112: Excelente (20 puntos) | V112: =VLOOKUP(TablaCalificaciones[[#This Row],[Metodología (nivel adecuado)]],PESOS!A$16:B$20,2,0) -> 20 | X112: Excelente (20 puntos) | Y112: =VLOOKUP(TablaCalificaciones[[#This Row],[Resultados y evidencia ]],PESOS!A$16:B$20,2,0) -> 20 | AA112: Excelente (10 puntos) | AB112: =VLOOKUP(TablaCalificaciones[[#This Row],[Coherencia y manejo del tiempo]],PESOS!A$25:B$29,2,0) -> 10 | AD112: Excelente (10 puntos) | AE112: =VLOOKUP(TablaCalificaciones[[#This Row],[Diapositivas como apoyo]],PESOS!A$25:B$29,2,0) -> 10 | AG112: Excelente (10 puntos) | AH112: =VLOOKUP(TablaCalificaciones[[#This Row],[Respuestas a preguntas]],PESOS!A$25:B$29,2,0) -> 10 | AJ112: Excelente (10 puntos) | AK112: =VLOOKUP(TablaCalificaciones[[#This Row],[Cierre: aporte a próximos pasos]],PESOS!A$25:B$29,2,0) -> 10
A113: 112 | B113: 46133.56 | C113: 46133.56 | D113: patricio.ponce.herrera@udla.edu.ec | E113: Patricio David Ponce Herrera | I113: Martes 21 | L113: Patricio David Ponce | M113: =CONCATENATE(TablaCalificaciones[[#This Row],[Seleccione su nombre (Evaluador)]],TablaCalificaciones[[#This Row],[Seleccione el nombre del Estudiante]]) -> Patricio David PonceLincango Ninahualpa Pablo Andrés | O113: Lincango Ninahualpa Pablo Andrés | R113: Excelente (20 puntos) | S113: =VLOOKUP(TablaCalificaciones[[#This Row],[Apertura: problema y objetivo ]],PESOS!A$16:B$20,2,0) -> 20 | U113: Excelente (20 puntos) | V113: =VLOOKUP(TablaCalificaciones[[#This Row],[Metodología (nivel adecuado)]],PESOS!A$16:B$20,2,0) -> 20 | X113: Excelente (20 puntos) | Y113: =VLOOKUP(TablaCalificaciones[[#This Row],[Resultados y evidencia ]],PESOS!A$16:B$20,2,0) -> 20 | AA113: Excelente (10 puntos) | AB113: =VLOOKUP(TablaCalificaciones[[#This Row],[Coherencia y manejo del tiempo]],PESOS!A$25:B$29,2,0) -> 10 | AD113: Muy bueno (8 puntos) | AE113: =VLOOKUP(TablaCalificaciones[[#This Row],[Diapositivas como apoyo]],PESOS!A$25:B$29,2,0) -> 8 | AG113: Muy bueno (8 puntos) | AH113: =VLOOKUP(TablaCalificaciones[[#This Row],[Respuestas a preguntas]],PESOS!A$25:B$29,2,0) -> 8 | AJ113: Excelente (10 puntos) | AK113: =VLOOKUP(TablaCalificaciones[[#This Row],[Cierre: aporte a próximos pasos]],PESOS!A$25:B$29,2,0) -> 10
... A601: 619 | B601: 46139.75 | C601: 46139.75 | D601: mariacristina.jimenez@udla.edu.ec | E601: María Cristina Jiménez Hernández | I601: Viernes 24 | L601: María Cristina Jiménez Hernández | M601: =CONCATENATE(TablaCalificaciones[[#This Row],[Seleccione su nombre (Evaluador)]],TablaCalificaciones[[#This Row],[Seleccione el nombre del Estudiante]]) -> María Cristina Jiménez HernándezRojas Calero César Augusto | O601: Rojas Calero César Augusto | R601: Excelente (20 puntos) | S601: =VLOOKUP(TablaCalificaciones[[#This Row],[Apertura: problema y objetivo ]],PESOS!A$16:B$20,2,0) -> 20 | U601: Excelente (20 puntos) | V601: =VLOOKUP(TablaCalificaciones[[#This Row],[Metodología (nivel adecuado)]],PESOS!A$16:B$20,2,0) -> 20 | X601: Excelente (20 puntos) | Y601: =VLOOKUP(TablaCalificaciones[[#This Row],[Resultados y evidencia ]],PESOS!A$16:B$20,2,0) -> 20 | AA601: Excelente (10 puntos) | AB601: =VLOOKUP(TablaCalificaciones[[#This Row],[Coherencia y manejo del tiempo]],PESOS!A$25:B$29,2,0) -> 10 | AD601: Excelente (10 puntos) | AE601: =VLOOKUP(TablaCalificaciones[[#This Row],[Diapositivas como apoyo]],PESOS!A$25:B$29,2,0) -> 10 | AG601: Excelente (10 puntos) | AH601: =VLOOKUP(TablaCalificaciones[[#This Row],[Respuestas a preguntas]],PESOS!A$25:B$29,2,0) -> 10 | AJ601: Excelente (10 puntos) | AK601: =VLOOKUP(TablaCalificaciones[[#This Row],[Cierre: aporte a próximos pasos]],PESOS!A$25:B$29,2,0) -> 10

Sheet PESOS
A1: Nivel (A) | B1: Puntos_20 (B) | C1: Puntos_10 (C)
A2: EXCELENTE | B2: 20 | C2: 10
A3: MUY BUENO | B3: 16 | C3: 8
A4: BUENO | B4: 12 | C4: 6
A5: REGULAR | B5: 8 | C5: 4
A6: INSUFICIENTE | B6: 4 | C6: 2
A15: (B) | B15: Puntos
A16: Excelente (20 puntos) | B16: 20
A17: Muy bueno (16 puntos) | B17: 16
A18: Bueno (12 puntos) | B18: 12
A19: Regular (8 puntos) | B19: 8
A20: Insuficiente (4 puntos) | B20: 4
A24: (C) | B24: Puntos
A25: Excelente (10 puntos) | B25: 10
A26: Muy bueno (8 puntos) | B26: 8
A27: Bueno (6 puntos) | B27: 6
A28: Regular (4 puntos) | B28: 4
A29: Insuficiente (2 puntos) | B29: 2

Sheet Detalle1
A1: Detalles de Cuenta de Seleccione su nombre (Evaluador) - Seleccione el nombre del Estudiante: Guevara Llanos Pahola Del Carmen
A3: Id | B3: Start time | C3: Completion time | D3: Email | E3: Name | F3: Total points | G3: Quiz feedback | H3: Grade posted time | I3: Seleccione el día de la defensa | J3: Points - Seleccione el día de la defensa | K3: Feedback - Seleccione el día de la defensa | L3: Seleccione su nombre (Evaluador) | M3: Control de duplicados | N3: Feedback - Seleccione su nombre (Evaluador) | O3: Seleccione el nombre del Estudiante | P3: Points - Seleccione el nombre del Estudiante | Q3: Feedback - Seleccione el nombre del Estudiante | R3: Apertura: problema y objetivo | S3: Points - Apertura: problema y objetivo | T3: Feedback - Apertura: problema y objetivo | U3: Metodología (nivel adecuado) | V3: Points - Metodología (nivel adecuado) | W3: Feedback - Metodología (nivel adecuado) | X3: Resultados y evidencia | Y3: Points - Resultados y evidencia | Z3: Feedback - Resultados y evidencia | AA3: Coherencia y manejo del tiempo | AB3: Points - Coherencia y manejo del tiempo | AC3: Feedback - Coherencia y manejo del tiempo | AD3: Diapositivas como apoyo | AE3: Points - Diapositivas como apoyo | AF3: Feedback - Diapositivas como apoyo | AG3: Respuestas a preguntas | AH3: Points - Respuestas a preguntas | AI3: Feedback - Respuestas a preguntas | AJ3: Cierre: aporte a próximos pasos | AK3: Points - Cierre: aporte a próximos pasos | AL3: Feedback - Cierre: aporte a próximos pasos | AM3: PUNTAJE APERTURA
A4: 413 | B4: 46135.679 | C4: 46135.68 | D4: patricio.ponce.herrera@udla.edu.ec | E4: Patricio David Ponce Herrera | I4: Jueves 23 | L4: Patricio David Ponce | M4: Patricio David PonceGuevara Llanos Pahola Del Carmen | O4: Guevara Llanos Pahola Del Carmen | R4: Excelente (20 puntos) | S4: 20 | U4: Muy bueno (16 puntos) | V4: 16 | X4: Excelente (20 puntos) | Y4: 20 | AA4: Bueno (6 puntos) | AB4: 6 | AD4: Excelente (10 puntos) | AE4: 10 | AG4: Excelente (10 puntos) | AH4: 10 | AJ4: Excelente (10 puntos) | AK4: 10
A5: 358 | B5: 46135.498 | C5: 46135.499 | D5: edison.chicaiza.salgado@udla.edu.ec | E5: Edison Ruben Chicaiza Salgado | I5: Jueves 23 | L5: Edison Chicaiza | M5: Edison ChicaizaGuevara Llanos Pahola Del Carmen | O5: Guevara Llanos Pahola Del Carmen | R5: Muy bueno (16 puntos) | S5: 16 | U5: Muy bueno (16 puntos) | V5: 16 | X5: Excelente (20 puntos) | Y5: 20 | AA5: Bueno (6 puntos) | AB5: 6 | AD5: Muy bueno (8 puntos) | AE5: 8 | AG5: Excelente (10 puntos) | AH5: 10 | AJ5: Muy bueno (8 puntos) | AK5: 8

Sheet Calculo
A3: Seleccione el nombre del Estudiante | B3: Cuenta de Seleccione su nombre (Evaluador) | C3: Promedio de Points - Apertura: problema y objetivo | D3: Promedio de Points - Metodología (nivel adecuado) | E3: Promedio de Points - Resultados y evidencia | F3: Promedio de Points - Coherencia y manejo del tiempo | G3: Promedio de Points - Diapositivas como apoyo | H3: Promedio de Points - Respuestas a preguntas | I3: Promedio de Points - Cierre: aporte a próximos pasos | J3: Nota ponderada | K3: Nota Rubrica Promedio | L3: Rubrica - Apertura: problema y objetivo | M3: Rubrica - Metodología (nivel adecuado) | N3: Rubrica - Resultados y evidencia | O3: Rubrica - Coherencia y manejo del tiempo | P3: Rubrica - Diapositivas como apoyo | Q3: Rubrica - Cierre: Respuestas a Preguntas | R3: Rubrica - Cierre: aporte a próximos pasos | S3: Docente Faltante 1 | T3: Docente Faltante 2 | U3: Docente Faltante 3
A4: Abad Anchundia Carlos Alejandro | B4: 3 | C4: 20 | D4: 16 | E4: 18.666667 | F4: 8.6666667 | G4: 8.6666667 | H4: 8.6666667 | I4: 8.6666667 | J4: =(C4+D4+E4+F4+G4+H4+I4) -> 89.333333 | K4: {=_xlfn.IFS(J4>=90,"Excelente",J4>=80,"Muy Bueno",J4>=75,"Bueno",J4>=65,"Regular",J4>=55,"Insuficiente")} -> Muy Bueno | L4: {=_xlfn.IFS(C4>=18,"Excelente",C4>=14,"Muy bueno",C4>=10,"Bueno",C4>=6,"Regular",C4<6,"Insuficiente")} -> Excelente | M4: {=_xlfn.IFS(D4>=18,"Excelente",D4>=14,"Muy bueno",D4>=10,"Bueno",D4>=6,"Regular",D4<6,"Insuficiente")} -> Muy bueno | N4: {=_xlfn.IFS(E4>=18,"Excelente",E4>=14,"Muy bueno",E4>=10,"Bueno",E4>=6,"Regular",E4<6,"Insuficiente")} -> Excelente | O4: {=_xlfn.IFS(F4>=9,"Excelente",F4>=7,"Muy bueno",F4>=5,"Bueno",F4>=3,"Regular",F4<3,"Insuficiente")} -> Muy bueno | P4: {=_xlfn.IFS(G4>=9,"Excelente",G4>=7,"Muy bueno",G4>=5,"Bueno",G4>=3,"Regular",G4<3,"Insuficiente")} -> Muy bueno | Q4: {=_xlfn.IFS(H4>=9,"Excelente",H4>=7,"Muy bueno",H4>=5,"Bueno",H4>=3,"Regular",H4<3,"Insuficiente")} -> Muy bueno | R4: {=_xlfn.IFS(I4>=9,"Excelente",I4>=7,"Muy bueno",I4>=5,"Bueno",I4>=3,"Regular",I4<3,"Insuficiente")} -> Muy bueno
A5: Acosta Balseca Belén Sarahí | B5: 3 | C5: 18.666667 | D5: 17.333333 | E5: 16 | F5: 8.6666667 | G5: 8.6666667 | H5: 8 | I5: 8.6666667 | J5: =(C5+D5+E5+F5+G5+H5+I5) -> 86 | K5: {=_xlfn.IFS(J5>=90,"Excelente",J5>=80,"Muy Bueno",J5>=75,"Bueno",J5>=65,"Regular",J5>=55,"Insuficiente")} -> Muy Bueno | L5: {=_xlfn.IFS(C5>=18,"Excelente",C5>=14,"Muy bueno",C5>=10,"Bueno",C5>=6,"Regular",C5<6,"Insuficiente")} -> Excelente | M5: {=_xlfn.IFS(D5>=18,"Excelente",D5>=14,"Muy bueno",D5>=10,"Bueno",D5>=6,"Regular",D5<6,"Insuficiente")} -> Muy bueno | N5: {=_xlfn.IFS(E5>=18,"Excelente",E5>=14,"Muy bueno",E5>=10,"Bueno",E5>=6,"Regular",E5<6,"Insuficiente")} -> Muy bueno | O5: {=_xlfn.IFS(F5>=9,"Excelente",F5>=7,"Muy bueno",F5>=5,"Bueno",F5>=3,"Regular",F5<3,"Insuficiente")} -> Muy bueno | P5: {=_xlfn.IFS(G5>=9,"Excelente",G5>=7,"Muy bueno",G5>=5,"Bueno",G5>=3,"Regular",G5<3,"Insuficiente")} -> Muy bueno | Q5: {=_xlfn.IFS(H5>=9,"Excelente",H5>=7,"Muy bueno",H5>=5,"Bueno",H5>=3,"Regular",H5<3,"Insuficiente")} -> Muy bueno | R5: {=_xlfn.IFS(I5>=9,"Excelente",I5>=7,"Muy bueno",I5>=5,"Bueno",I5>=3,"Regular",I5<3,"Insuficiente")} -> Muy bueno
A6: Acosta Polanco Álvaro Marcelo | B6: 3 | C6: 18.666667 | D6: 18.666667 | E6: 18.666667 | F6: 9.3333333 | G6: 8.6666667 | H6: 8.6666667 | I6: 9.3333333 | J6: =(C6+D6+E6+F6+G6+H6+I6) -> 92 | K6: {=_xlfn.IFS(J6>=90,"Excelente",J6>=80,"Muy Bueno",J6>=75,"Bueno",J6>=65,"Regular",J6>=55,"Insuficiente")} -> Excelente | L6: {=_xlfn.IFS(C6>=18,"Excelente",C6>=14,"Muy bueno",C6>=10,"Bueno",C6>=6,"Regular",C6<6,"Insuficiente")} -> Excelente | M6: {=_xlfn.IFS(D6>=18,"Excelente",D6>=14,"Muy bueno",D6>=10,"Bueno",D6>=6,"Regular",D6<6,"Insuficiente")} -> Excelente | N6: {=_xlfn.IFS(E6>=18,"Excelente",E6>=14,"Muy bueno",E6>=10,"Bueno",E6>=6,"Regular",E6<6,"Insuficiente")} -> Excelente | O6: {=_xlfn.IFS(F6>=9,"Excelente",F6>=7,"Muy bueno",F6>=5,"Bueno",F6>=3,"Regular",F6<3,"Insuficiente")} -> Excelente | P6: {=_xlfn.IFS(G6>=9,"Excelente",G6>=7,"Muy bueno",G6>=5,"Bueno",G6>=3,"Regular",G6<3,"Insuficiente")} -> Muy bueno | Q6: {=_xlfn.IFS(H6>=9,"Excelente",H6>=7,"Muy bueno",H6>=5,"Bueno",H6>=3,"Regular",H6<3,"Insuficiente")} -> Muy bueno | R6: {=_xlfn.IFS(I6>=9,"Excelente",I6>=7,"Muy bueno",I6>=5,"Bueno",I6>=3,"Regular",I6<3,"Insuficiente")} -> Excelente
A7: Aguaisa Moreno Victor Andres | B7: 3 | C7: 20 | D7: 20 | E7: 20 | F7: 10 | G7: 10 | H7: 10 | I7: 10 | J7: =(C7+D7+E7+F7+G7+H7+I7) -> 100 | K7: {=_xlfn.IFS(J7>=90,"Excelente",J7>=80,"Muy Bueno",J7>=75,"Bueno",J7>=65,"Regular",J7>=55,"Insuficiente")} -> Excelente | L7: {=_xlfn.IFS(C7>=18,"Excelente",C7>=14,"Muy bueno",C7>=10,"Bueno",C7>=6,"Regular",C7<6,"Insuficiente")} -> Excelente | M7: {=_xlfn.IFS(D7>=18,"Excelente",D7>=14,"Muy bueno",D7>=10,"Bueno",D7>=6,"Regular",D7<6,"Insuficiente")} -> Excelente | N7: {=_xlfn.IFS(E7>=18,"Excelente",E7>=14,"Muy bueno",E7>=10,"Bueno",E7>=6,"Regular",E7<6,"Insuficiente")} -> Excelente | O7: {=_xlfn.IFS(F7>=9,"Excelente",F7>=7,"Muy bueno",F7>=5,"Bueno",F7>=3,"Regular",F7<3,"Insuficiente")} -> Excelente | P7: {=_xlfn.IFS(G7>=9,"Excelente",G7>=7,"Muy bueno",G7>=5,"Bueno",G7>=3,"Regular",G7<3,"Insuficiente")} -> Excelente | Q7: {=_xlfn.IFS(H7>=9,"Excelente",H7>=7,"Muy bueno",H7>=5,"Bueno",H7>=3,"Regular",H7<3,"Insuficiente")} -> Excelente | R7: {=_xlfn.IFS(I7>=9,"Excelente",I7>=7,"Muy bueno",I7>=5,"Bueno",I7>=3,"Regular",I7<3,"Insuficiente")} -> Excelente
A8: Almeida Mera Emilio Andrés | B8: 3 | C8: 20 | D8: 18.666667 | E8: 18.666667 | F8: 10 | G8: 10 | H8: 8 | I8: 10 | J8: =(C8+D8+E8+F8+G8+H8+I8) -> 95.333333 | K8: {=_xlfn.IFS(J8>=90,"Excelente",J8>=80,"Muy Bueno",J8>=75,"Bueno",J8>=65,"Regular",J8>=55,"Insuficiente")} -> Excelente | L8: {=_xlfn.IFS(C8>=18,"Excelente",C8>=14,"Muy bueno",C8>=10,"Bueno",C8>=6,"Regular",C8<6,"Insuficiente")} -> Excelente | M8: {=_xlfn.IFS(D8>=18,"Excelente",D8>=14,"Muy bueno",D8>=10,"Bueno",D8>=6,"Regular",D8<6,"Insuficiente")} -> Excelente | N8: {=_xlfn.IFS(E8>=18,"Excelente",E8>=14,"Muy bueno",E8>=10,"Bueno",E8>=6,"Regular",E8<6,"Insuficiente")} -> Excelente | O8: {=_xlfn.IFS(F8>=9,"Excelente",F8>=7,"Muy bueno",F8>=5,"Bueno",F8>=3,"Regular",F8<3,"Insuficiente")} -> Excelente | P8: {=_xlfn.IFS(G8>=9,"Excelente",G8>=7,"Muy bueno",G8>=5,"Bueno",G8>=3,"Regular",G8<3,"Insuficiente")} -> Excelente | Q8: {=_xlfn.IFS(H8>=9,"Excelente",H8>=7,"Muy bueno",H8>=5,"Bueno",H8>=3,"Regular",H8<3,"Insuficiente")} -> Muy bueno | R8: {=_xlfn.IFS(I8>=9,"Excelente",I8>=7,"Muy bueno",I8>=5,"Bueno",I8>=3,"Regular",I8<3,"Insuficiente")} -> Excelente
A9: Álvarez Vásquez Marcelo | B9: 3 | C9: 18.666667 | D9: 16 | E9: 16 | F9: 8.6666667 | G9: 10 | H9: 7.3333333 | I9: 9.3333333 | J9: =(C9+D9+E9+F9+G9+H9+I9) -> 86 | K9: {=_xlfn.IFS(J9>=90,"Excelente",J9>=80,"Muy Bueno",J9>=75,"Bueno",J9>=65,"Regular",J9>=55,"Insuficiente")} -> Muy Bueno | L9: {=_xlfn.IFS(C9>=18,"Excelente",C9>=14,"Muy bueno",C9>=10,"Bueno",C9>=6,"Regular",C9<6,"Insuficiente")} -> Excelente | M9: {=_xlfn.IFS(D9>=18,"Excelente",D9>=14,"Muy bueno",D9>=10,"Bueno",D9>=6,"Regular",D9<6,"Insuficiente")} -> Muy bueno | N9: {=_xlfn.IFS(E9>=18,"Excelente",E9>=14,"Muy bueno",E9>=10,"Bueno",E9>=6,"Regular",E9<6,"Insuficiente")} -> Muy bueno | O9: {=_xlfn.IFS(F9>=9,"Excelente",F9>=7,"Muy bueno",F9>=5,"Bueno",F9>=3,"Regular",F9<3,"Insuficiente")} -> Muy bueno | P9: {=_xlfn.IFS(G9>=9,"Excelente",G9>=7,"Muy bueno",G9>=5,"Bueno",G9>=3,"Regular",G9<3,"Insuficiente")} -> Excelente | Q9: {=_xlfn.IFS(H9>=9,"Excelente",H9>=7,"Muy bueno",H9>=5,"Bueno",H9>=3,"Regular",H9<3,"Insuficiente")} -> Muy bueno | R9: {=_xlfn.IFS(I9>=9,"Excelente",I9>=7,"Muy bueno",I9>=5,"Bueno",I9>=3,"Regular",I9<3,"Insuficiente")} -> Excelente
A10: Andrade Mulki Esteban Nicolas | B10: 3 | C10: 20 | D10: 20 | E10: 18.666667 | F10: 10 | G10: 10 | H10: 10 | I10: 10 | J10: =(C10+D10+E10+F10+G10+H10+I10) -> 98.666667 | K10: {=_xlfn.IFS(J10>=90,"Excelente",J10>=80,"Muy Bueno",J10>=75,"Bueno",J10>=65,"Regular",J10>=55,"Insuficiente")} -> Excelente | L10: {=_xlfn.IFS(C10>=18,"Excelente",C10>=14,"Muy bueno",C10>=10,"Bueno",C10>=6,"Regular",C10<6,"Insuficiente")} -> Excelente | M10: {=_xlfn.IFS(D10>=18,"Excelente",D10>=14,"Muy bueno",D10>=10,"Bueno",D10>=6,"Regular",D10<6,"Insuficiente")} -> Excelente | N10: {=_xlfn.IFS(E10>=18,"Excelente",E10>=14,"Muy bueno",E10>=10,"Bueno",E10>=6,"Regular",E10<6,"Insuficiente")} -> Excelente | O10: {=_xlfn.IFS(F10>=9,"Excelente",F10>=7,"Muy bueno",F10>=5,"Bueno",F10>=3,"Regular",F10<3,"Insuficiente")} -> Excelente | P10: {=_xlfn.IFS(G10>=9,"Excelente",G10>=7,"Muy bueno",G10>=5,"Bueno",G10>=3,"Regular",G10<3,"Insuficiente")} -> Excelente | Q10: {=_xlfn.IFS(H10>=9,"Excelente",H10>=7,"Muy bueno",H10>=5,"Bueno",H10>=3,"Regular",H10<3,"Insuficiente")} -> Excelente | R10: {=_xlfn.IFS(I10>=9,"Excelente",I10>=7,"Muy bueno",I10>=5,"Bueno",I10>=3,"Regular",I10<3,"Insuficiente")} -> Excelente
A11: Angulo Dávila Carlos Andrés | B11: 3 | C11: 20 | D11: 18.666667 | E11: 20 | F11: 10 | G11: 10 | H11: 9.3333333 | I11: 10 | J11: =(C11+D11+E11+F11+G11+H11+I11) -> 98 | K11: {=_xlfn.IFS(J11>=90,"Excelente",J11>=80,"Muy Bueno",J11>=75,"Bueno",J11>=65,"Regular",J11>=55,"Insuficiente")} -> Excelente | L11: {=_xlfn.IFS(C11>=18,"Excelente",C11>=14,"Muy bueno",C11>=10,"Bueno",C11>=6,"Regular",C11<6,"Insuficiente")} -> Excelente | M11: {=_xlfn.IFS(D11>=18,"Excelente",D11>=14,"Muy bueno",D11>=10,"Bueno",D11>=6,"Regular",D11<6,"Insuficiente")} -> Excelente | N11: {=_xlfn.IFS(E11>=18,"Excelente",E11>=14,"Muy bueno",E11>=10,"Bueno",E11>=6,"Regular",E11<6,"Insuficiente")} -> Excelente | O11: {=_xlfn.IFS(F11>=9,"Excelente",F11>=7,"Muy bueno",F11>=5,"Bueno",F11>=3,"Regular",F11<3,"Insuficiente")} -> Excelente | P11: {=_xlfn.IFS(G11>=9,"Excelente",G11>=7,"Muy bueno",G11>=5,"Bueno",G11>=3,"Regular",G11<3,"Insuficiente")} -> Excelente | Q11: {=_xlfn.IFS(H11>=9,"Excelente",H11>=7,"Muy bueno",H11>=5,"Bueno",H11>=3,"Regular",H11<3,"Insuficiente")} -> Excelente | R11: {=_xlfn.IFS(I11>=9,"Excelente",I11>=7,"Muy bueno",I11>=5,"Bueno",I11>=3,"Regular",I11<3,"Insuficiente")} -> Excelente
A12: Arévalo Yépez Lucio Plácido | B12: 3 | C12: 20 | D12: 20 | E12: 20 | F12: 9.3333333 | G12: 8.6666667 | H12: 8.6666667 | I12: 9.3333333 | J12: =(C12+D12+E12+F12+G12+H12+I12) -> 96 | K12: {=_xlfn.IFS(J12>=90,"Excelente",J12>=80,"Muy Bueno",J12>=75,"Bueno",J12>=65,"Regular",J12>=55,"Insuficiente")} -> Excelente | L12: {=_xlfn.IFS(C12>=18,"Excelente",C12>=14,"Muy bueno",C12>=10,"Bueno",C12>=6,"Regular",C12<6,"Insuficiente")} -> Excelente | M12: {=_xlfn.IFS(D12>=18,"Excelente",D12>=14,"Muy bueno",D12>=10,"Bueno",D12>=6,"Regular",D12<6,"Insuficiente")} -> Excelente | N12: {=_xlfn.IFS(E12>=18,"Excelente",E12>=14,"Muy bueno",E12>=10,"Bueno",E12>=6,"Regular",E12<6,"Insuficiente")} -> Excelente | O12: {=_xlfn.IFS(F12>=9,"Excelente",F12>=7,"Muy bueno",F12>=5,"Bueno",F12>=3,"Regular",F12<3,"Insuficiente")} -> Excelente | P12: {=_xlfn.IFS(G12>=9,"Excelente",G12>=7,"Muy bueno",G12>=5,"Bueno",G12>=3,"Regular",G12<3,"Insuficiente")} -> Muy bueno | Q12: {=_xlfn.IFS(H12>=9,"Excelente",H12>=7,"Muy bueno",H12>=5,"Bueno",H12>=3,"Regular",H12<3,"Insuficiente")} -> Muy bueno | R12: {=_xlfn.IFS(I12>=9,"Excelente",I12>=7,"Muy bueno",I12>=5,"Bueno",I12>=3,"Regular",I12<3,"Insuficiente")} -> Excelente
A13: Arias Basantes Jeanpierre | B13: 3 | C13: 20 | D13: 20 | E13: 20 | F13: 10 | G13: 10 | H13: 10 | I13: 10 | J13: =(C13+D13+E13+F13+G13+H13+I13) -> 100 | K13: {=_xlfn.IFS(J13>=90,"Excelente",J13>=80,"Muy Bueno",J13>=75,"Bueno",J13>=65,"Regular",J13>=55,"Insuficiente")} -> Excelente | L13: {=_xlfn.IFS(C13>=18,"Excelente",C13>=14,"Muy bueno",C13>=10,"Bueno",C13>=6,"Regular",C13<6,"Insuficiente")} -> Excelente | M13: {=_xlfn.IFS(D13>=18,"Excelente",D13>=14,"Muy bueno",D13>=10,"Bueno",D13>=6,"Regular",D13<6,"Insuficiente")} -> Excelente | N13: {=_xlfn.IFS(E13>=18,"Excelente",E13>=14,"Muy bueno",E13>=10,"Bueno",E13>=6,"Regular",E13<6,"Insuficiente")} -> Excelente | O13: {=_xlfn.IFS(F13>=9,"Excelente",F13>=7,"Muy bueno",F13>=5,"Bueno",F13>=3,"Regular",F13<3,"Insuficiente")} -> Excelente | P13: {=_xlfn.IFS(G13>=9,"Excelente",G13>=7,"Muy bueno",G13>=5,"Bueno",G13>=3,"Regular",G13<3,"Insuficiente")} -> Excelente | Q13: {=_xlfn.IFS(H13>=9,"Excelente",H13>=7,"Muy bueno",H13>=5,"Bueno",H13>=3,"Regular",H13<3,"Insuficiente")} -> Excelente | R13: {=_xlfn.IFS(I13>=9,"Excelente",I13>=7,"Muy bueno",I13>=5,"Bueno",I13>=3,"Regular",I13<3,"Insuficiente")} -> Excelente
A14: Armas Torres Diego Sebastian | B14: 3 | C14: 20 | D14: 20 | E14: 20 | F14: 9.3333333 | G14: 8.6666667 | H14: 9.3333333 | I14: 10 | J14: =(C14+D14+E14+F14+G14+H14+I14) -> 97.333333 | K14: {=_xlfn.IFS(J14>=90,"Excelente",J14>=80,"Muy Bueno",J14>=75,"Bueno",J14>=65,"Regular",J14>=55,"Insuficiente")} -> Excelente | L14: {=_xlfn.IFS(C14>=18,"Excelente",C14>=14,"Muy bueno",C14>=10,"Bueno",C14>=6,"Regular",C14<6,"Insuficiente")} -> Excelente | M14: {=_xlfn.IFS(D14>=18,"Excelente",D14>=14,"Muy bueno",D14>=10,"Bueno",D14>=6,"Regular",D14<6,"Insuficiente")} -> Excelente | N14: {=_xlfn.IFS(E14>=18,"Excelente",E14>=14,"Muy bueno",E14>=10,"Bueno",E14>=6,"Regular",E14<6,"Insuficiente")} -> Excelente | O14: {=_xlfn.IFS(F14>=9,"Excelente",F14>=7,"Muy bueno",F14>=5,"Bueno",F14>=3,"Regular",F14<3,"Insuficiente")} -> Excelente | P14: {=_xlfn.IFS(G14>=9,"Excelente",G14>=7,"Muy bueno",G14>=5,"Bueno",G14>=3,"Regular",G14<3,"Insuficiente")} -> Muy bueno | Q14: {=_xlfn.IFS(H14>=9,"Excelente",H14>=7,"Muy bueno",H14>=5,"Bueno",H14>=3,"Regular",H14<3,"Insuficiente")} -> Excelente | R14: {=_xlfn.IFS(I14>=9,"Excelente",I14>=7,"Muy bueno",I14>=5,"Bueno",I14>=3,"Regular",I14<3,"Insuficiente")} -> Excelente
A15: Ávila Jumbo Mateo Danilo | B15: 3 | C15: 20 | D15: 20 | E15: 20 | F15: 10 | G15: 10 | H15: 10 | I15: 10 | J15: =(C15+D15+E15+F15+G15+H15+I15) -> 100 | K15: {=_xlfn.IFS(J15>=90,"Excelente",J15>=80,"Muy Bueno",J15>=75,"Bueno",J15>=65,"Regular",J15>=55,"Insuficiente")} -> Excelente | L15: {=_xlfn.IFS(C15>=18,"Excelente",C15>=14,"Muy bueno",C15>=10,"Bueno",C15>=6,"Regular",C15<6,"Insuficiente")} -> Excelente | M15: {=_xlfn.IFS(D15>=18,"Excelente",D15>=14,"Muy bueno",D15>=10,"Bueno",D15>=6,"Regular",D15<6,"Insuficiente")} -> Excelente | N15: {=_xlfn.IFS(E15>=18,"Excelente",E15>=14,"Muy bueno",E15>=10,"Bueno",E15>=6,"Regular",E15<6,"Insuficiente")} -> Excelente | O15: {=_xlfn.IFS(F15>=9,"Excelente",F15>=7,"Muy bueno",F15>=5,"Bueno",F15>=3,"Regular",F15<3,"Insuficiente")} -> Excelente | P15: {=_xlfn.IFS(G15>=9,"Excelente",G15>=7,"Muy bueno",G15>=5,"Bueno",G15>=3,"Regular",G15<3,"Insuficiente")} -> Excelente | Q15: {=_xlfn.IFS(H15>=9,"Excelente",H15>=7,"Muy bueno",H15>=5,"Bueno",H15>=3,"Regular",H15<3,"Insuficiente")} -> Excelente | R15: {=_xlfn.IFS(I15>=9,"Excelente",I15>=7,"Muy bueno",I15>=5,"Bueno",I15>=3,"Regular",I15<3,"Insuficiente")} -> Excelente
... A203: Zurita Landázuri Diego Alejandro | B203: 3 | C203: 16 | D203: 16 | E203: 16 | F203: 6 | G203: 8 | H203: 6 | I203: 6 | J203: =(C203+D203+E203+F203+G203+H203+I203) -> 74 | K203: {=_xlfn.IFS(J203>=90,"Excelente",J203>=80,"Muy Bueno",J203>=75,"Bueno",J203>=65,"Regular",J203>=55,"Insuficiente")} -> Regular | L203: {=_xlfn.IFS(C203>=18,"Excelente",C203>=14,"Muy bueno",C203>=10,"Bueno",C203>=6,"Regular",C203<6,"Insuficiente")} -> Muy bueno | M203: {=_xlfn.IFS(D203>=18,"Excelente",D203>=14,"Muy bueno",D203>=10,"Bueno",D203>=6,"Regular",D203<6,"Insuficiente")} -> Muy bueno | N203: {=_xlfn.IFS(E203>=18,"Excelente",E203>=14,"Muy bueno",E203>=10,"Bueno",E203>=6,"Regular",E203<6,"Insuficiente")} -> Muy bueno | O203: {=_xlfn.IFS(F203>=9,"Excelente",F203>=7,"Muy bueno",F203>=5,"Bueno",F203>=3,"Regular",F203<3,"Insuficiente")} -> Bueno | P203: {=_xlfn.IFS(G203>=9,"Excelente",G203>=7,"Muy bueno",G203>=5,"Bueno",G203>=3,"Regular",G203<3,"Insuficiente")} -> Muy bueno | Q203: {=_xlfn.IFS(H203>=9,"Excelente",H203>=7,"Muy bueno",H203>=5,"Bueno",H203>=3,"Regular",H203<3,"Insuficiente")} -> Bueno | R203: {=_xlfn.IFS(I203>=9,"Excelente",I203>=7,"Muy bueno",I203>=5,"Bueno",I203>=3,"Regular",I203<3,"Insuficiente")} -> Bueno
A204: Total general | B204: 600 | C204: 19.466667 | D204: 19.173333 | E204: 18.966667 | F204: 9.3766667 | G204: 9.4533333 | H204: 9.1133333 | I204: 9.4533333 | L204: {=_xlfn.IFS(C204>=18,"Excelente",C204>=14,"Muy bueno",C204>=10,"Bueno",C204>=6,"Regular",C204<6,"Insuficiente")} -> Excelente | M204: {=_xlfn.IFS(D204>=18,"Excelente",D204>=14,"Muy bueno",D204>=10,"Bueno",D204>=6,"Regular",D204<6,"Insuficiente")} -> Excelente | N204: {=_xlfn.IFS(E204>=18,"Excelente",E204>=14,"Muy bueno",E204>=10,"Bueno",E204>=6,"Regular",E204<6,"Insuficiente")} -> Excelente | O204: {=_xlfn.IFS(F204>=9,"Excelente",F204>=7,"Muy bueno",F204>=5,"Bueno",F204>=3,"Regular",F204<3,"Insuficiente")} -> Excelente | P204: {=_xlfn.IFS(G204>=9,"Excelente",G204>=7,"Muy bueno",G204>=5,"Bueno",G204>=3,"Regular",G204<3,"Insuficiente")} -> Excelente | Q204: {=_xlfn.IFS(H204>=9,"Excelente",H204>=7,"Muy bueno",H204>=5,"Bueno",H204>=3,"Regular",H204<3,"Insuficiente")} -> Excelente | R204: {=_xlfn.IFS(I204>=9,"Excelente",I204>=7,"Muy bueno",I204>=5,"Bueno",I204>=3,"Regular",I204<3,"Insuficiente")} -> Excelente

Sheet Seguimiento
A1: Seleccione el nombre del Estudiante | B1: Cuenta de Seleccione su nombre (Evaluador) | C1: Promedio de Points - Apertura: problema y objetivo | D1: Promedio de Points - Metodología (nivel adecuado) | E1: Promedio de Points - Resultados y evidencia | F1: Promedio de Points - Coherencia y manejo del tiempo | G1: Promedio de Points - Diapositivas como apoyo | H1: Promedio de Points - Respuestas a preguntas | I1: Promedio de Points - Cierre: aporte a próximos pasos | J1: Nota ponderada | K1: Nota Rubrica
A2: Abad Anchundia Carlos Alejandro | B2: 3 | C2: 20 | D2: 16 | E2: 18.666667 | F2: 8.6666667 | G2: 8.6666667 | H2: 8.6666667 | I2: 8.6666667 | J2: =(C2+D2+E2+F2+G2+H2+I2) -> 89.333333 | K2: {=_xlfn.IFS(J2>=90,"Excelente",J2>=80,"Muy Bueno",J2>=75,"Bueno",J2>=65,"Regular",J2>=55,"Insuficiente")} -> Muy Bueno
A3: Acosta Balseca Belén Sarahí | B3: 3 | C3: 18.666667 | D3: 17.333333 | E3: 16 | F3: 8.6666667 | G3: 8.6666667 | H3: 8 | I3: 8.6666667 | J3: =(C3+D3+E3+F3+G3+H3+I3) -> 86 | K3: {=_xlfn.IFS(J3>=90,"Excelente",J3>=80,"Muy Bueno",J3>=75,"Bueno",J3>=65,"Regular",J3>=55,"Insuficiente")} -> Muy Bueno
A4: Acosta Polanco Álvaro Marcelo | B4: 3 | C4: 18.666667 | D4: 18.666667 | E4: 18.666667 | F4: 9.3333333 | G4: 8.6666667 | H4: 8.6666667 | I4: 9.3333333 | J4: =(C4+D4+E4+F4+G4+H4+I4) -> 92 | K4: {=_xlfn.IFS(J4>=90,"Excelente",J4>=80,"Muy Bueno",J4>=75,"Bueno",J4>=65,"Regular",J4>=55,"Insuficiente")} -> Excelente
A5: Aguaisa Moreno Victor Andres | B5: 3 | C5: 20 | D5: 20 | E5: 20 | F5: 10 | G5: 10 | H5: 10 | I5: 10 | J5: =(C5+D5+E5+F5+G5+H5+I5) -> 100 | K5: {=_xlfn.IFS(J5>=90,"Excelente",J5>=80,"Muy Bueno",J5>=75,"Bueno",J5>=65,"Regular",J5>=55,"Insuficiente")} -> Excelente
A6: Almeida Mera Emilio Andrés | B6: 3 | C6: 20 | D6: 18.666667 | E6: 18.666667 | F6: 10 | G6: 10 | H6: 8 | I6: 10 | J6: =(C6+D6+E6+F6+G6+H6+I6) -> 95.333333 | K6: {=_xlfn.IFS(J6>=90,"Excelente",J6>=80,"Muy Bueno",J6>=75,"Bueno",J6>=65,"Regular",J6>=55,"Insuficiente")} -> Excelente
A7: Álvarez Vásquez Marcelo | B7: 3 | C7: 18.666667 | D7: 16 | E7: 16 | F7: 8.6666667 | G7: 10 | H7: 7.3333333 | I7: 9.3333333 | J7: =(C7+D7+E7+F7+G7+H7+I7) -> 86 | K7: {=_xlfn.IFS(J7>=90,"Excelente",J7>=80,"Muy Bueno",J7>=75,"Bueno",J7>=65,"Regular",J7>=55,"Insuficiente")} -> Muy Bueno
